[2024-04-18T02:48:02.975+0000] {local_task_job_runner.py:120} INFO - ::group::Pre task execution logs
[2024-04-18T02:48:03.073+0000] {taskinstance.py:2073} INFO - Dependencies all met for dep_context=non-requeueable deps ti=<TaskInstance: example_sensors.wait_for_file manual__2024-04-18T02:47:33.787232+00:00 [queued]>
[2024-04-18T02:48:03.107+0000] {taskinstance.py:2073} INFO - Dependencies all met for dep_context=requeueable deps ti=<TaskInstance: example_sensors.wait_for_file manual__2024-04-18T02:47:33.787232+00:00 [queued]>
[2024-04-18T02:48:03.109+0000] {taskinstance.py:2303} INFO - Starting attempt 1 of 1
[2024-04-18T02:48:03.148+0000] {taskinstance.py:2327} INFO - Executing <Task(FileSensor): wait_for_file> on 2024-04-18 02:47:33.787232+00:00
[2024-04-18T02:48:03.161+0000] {warnings.py:110} WARNING - /home/***/.local/lib/python3.12/site-packages/***/task/task_runner/standard_task_runner.py:61: DeprecationWarning: This process (pid=1613) is multi-threaded, use of fork() may lead to deadlocks in the child.
  pid = os.fork()

[2024-04-18T02:48:03.163+0000] {standard_task_runner.py:90} INFO - Running: ['***', 'tasks', 'run', 'example_sensors', 'wait_for_file', 'manual__2024-04-18T02:47:33.787232+00:00', '--job-id', '21', '--raw', '--subdir', '/home/***/.local/lib/python3.12/site-packages/***/example_dags/example_sensors.py', '--cfg-path', '/tmp/tmp4s95fk8z']
[2024-04-18T02:48:03.166+0000] {standard_task_runner.py:63} INFO - Started process 1617 to run task
[2024-04-18T02:48:03.168+0000] {standard_task_runner.py:91} INFO - Job 21: Subtask wait_for_file
[2024-04-18T02:48:03.286+0000] {task_command.py:426} INFO - Running <TaskInstance: example_sensors.wait_for_file manual__2024-04-18T02:47:33.787232+00:00 [running]> on host f31c3e7472ea
[2024-04-18T02:48:03.594+0000] {taskinstance.py:2644} INFO - Exporting env vars: AIRFLOW_CTX_DAG_OWNER='***' AIRFLOW_CTX_DAG_ID='example_sensors' AIRFLOW_CTX_TASK_ID='wait_for_file' AIRFLOW_CTX_EXECUTION_DATE='2024-04-18T02:47:33.787232+00:00' AIRFLOW_CTX_TRY_NUMBER='1' AIRFLOW_CTX_DAG_RUN_ID='manual__2024-04-18T02:47:33.787232+00:00'
[2024-04-18T02:48:03.597+0000] {taskinstance.py:430} INFO - ::endgroup::
[2024-04-18T02:48:03.598+0000] {baseoperator.py:399} WARNING - FileSensor.execute cannot be called outside TaskInstance!
[2024-04-18T02:48:03.614+0000] {taskinstance.py:441} INFO - ::group::Post task execution logs
[2024-04-18T02:48:03.638+0000] {taskinstance.py:2890} ERROR - Task failed with exception
Traceback (most recent call last):
  File "/home/airflow/.local/lib/python3.12/site-packages/airflow/models/taskinstance.py", line 465, in _execute_task
    result = _execute_callable(context=context, **execute_callable_kwargs)
             ^^^^^^^^^^^^^^^^^^^^^^^^^^^^^^^^^^^^^^^^^^^^^^^^^^^^^^^^^^^^^
  File "/home/airflow/.local/lib/python3.12/site-packages/airflow/models/taskinstance.py", line 432, in _execute_callable
    return execute_callable(context=context, **execute_callable_kwargs)
           ^^^^^^^^^^^^^^^^^^^^^^^^^^^^^^^^^^^^^^^^^^^^^^^^^^^^^^^^^^^^
  File "/home/airflow/.local/lib/python3.12/site-packages/airflow/models/baseoperator.py", line 400, in wrapper
    return func(self, *args, **kwargs)
           ^^^^^^^^^^^^^^^^^^^^^^^^^^^
  File "/home/airflow/.local/lib/python3.12/site-packages/airflow/sensors/filesystem.py", line 99, in execute
    super().execute(context=context)
  File "/home/airflow/.local/lib/python3.12/site-packages/airflow/models/baseoperator.py", line 400, in wrapper
    return func(self, *args, **kwargs)
           ^^^^^^^^^^^^^^^^^^^^^^^^^^^
  File "/home/airflow/.local/lib/python3.12/site-packages/airflow/sensors/base.py", line 264, in execute
    raise e
  File "/home/airflow/.local/lib/python3.12/site-packages/airflow/sensors/base.py", line 246, in execute
    poke_return = self.poke(context)
                  ^^^^^^^^^^^^^^^^^^
  File "/home/airflow/.local/lib/python3.12/site-packages/airflow/sensors/filesystem.py", line 85, in poke
    self.log.info("Poking for file %s", self.path)
                                        ^^^^^^^^^
  File "/usr/local/lib/python3.12/functools.py", line 995, in __get__
    val = self.func(instance)
          ^^^^^^^^^^^^^^^^^^^
  File "/home/airflow/.local/lib/python3.12/site-packages/airflow/sensors/filesystem.py", line 79, in path
    hook = FSHook(self.fs_conn_id)
           ^^^^^^^^^^^^^^^^^^^^^^^
  File "/home/airflow/.local/lib/python3.12/site-packages/airflow/hooks/filesystem.py", line 64, in __init__
    conn = self.get_connection(fs_conn_id)
           ^^^^^^^^^^^^^^^^^^^^^^^^^^^^^^^
  File "/home/airflow/.local/lib/python3.12/site-packages/airflow/hooks/base.py", line 83, in get_connection
    conn = Connection.get_connection_from_secrets(conn_id)
           ^^^^^^^^^^^^^^^^^^^^^^^^^^^^^^^^^^^^^^^^^^^^^^^
  File "/home/airflow/.local/lib/python3.12/site-packages/airflow/models/connection.py", line 519, in get_connection_from_secrets
    raise AirflowNotFoundException(f"The conn_id `{conn_id}` isn't defined")
airflow.exceptions.AirflowNotFoundException: The conn_id `fs_default` isn't defined
[2024-04-18T02:48:03.658+0000] {taskinstance.py:1205} INFO - Marking task as FAILED. dag_id=example_sensors, task_id=wait_for_file, execution_date=20240418T024733, start_date=20240418T024803, end_date=20240418T024803
[2024-04-18T02:48:03.700+0000] {standard_task_runner.py:110} ERROR - Failed to execute job 21 for task wait_for_file (The conn_id `fs_default` isn't defined; 1617)
[2024-04-18T02:48:03.757+0000] {local_task_job_runner.py:240} INFO - Task exited with return code 1
[2024-04-18T02:48:03.840+0000] {taskinstance.py:3482} INFO - 0 downstream tasks scheduled from follow-on schedule check
[2024-04-18T02:48:03.850+0000] {local_task_job_runner.py:222} INFO - ::endgroup::
